2020-05-22 23:47:49,393	[ERROR]	/home/huchida/work/venv_voice_mapping/lib64/python3.7/site-packages/django/core/handlers/exception.py(Line:77)	Invalid HTTP_HOST header: '18.216.231.209:80'. You may need to add '18.216.231.209' to ALLOWED_HOSTS.
2020-05-23 00:11:08,510	[ERROR]	/home/huchida/work/venv_voice_mapping/lib64/python3.7/site-packages/django/core/handlers/exception.py(Line:77)	Invalid HTTP_HOST header: '18.216.231.209'. You may need to add '18.216.231.209' to ALLOWED_HOSTS.
2020-05-23 01:12:20,424	[ERROR]	/home/huchida/work/venv_voice_mapping/lib64/python3.7/site-packages/django/core/handlers/exception.py(Line:77)	Invalid HTTP_HOST header: '18.216.231.209:80'. You may need to add '18.216.231.209' to ALLOWED_HOSTS.
2020-05-23 02:32:43,629	[ERROR]	/home/huchida/work/venv_voice_mapping/lib64/python3.7/site-packages/django/core/handlers/exception.py(Line:77)	Invalid HTTP_HOST header: '18.216.231.209'. You may need to add '18.216.231.209' to ALLOWED_HOSTS.
2020-05-23 02:35:36,001	[ERROR]	/home/huchida/work/venv_voice_mapping/lib64/python3.7/site-packages/django/core/handlers/exception.py(Line:77)	Invalid HTTP_HOST header: '127.0.0.1'. You may need to add '127.0.0.1' to ALLOWED_HOSTS.
2020-05-23 02:43:19,973	[ERROR]	/home/huchida/work/venv_voice_mapping/lib64/python3.7/site-packages/django/core/handlers/exception.py(Line:77)	Invalid HTTP_HOST header: '127.0.0.1:8000'. You may need to add '127.0.0.1' to ALLOWED_HOSTS.
2020-05-23 03:01:35,639	[ERROR]	/home/huchida/work/venv_voice_mapping/lib64/python3.7/site-packages/django/core/handlers/exception.py(Line:77)	Invalid HTTP_HOST header: '18.216.231.209:80'. You may need to add '18.216.231.209' to ALLOWED_HOSTS.
2020-05-23 03:25:46,275	[ERROR]	/home/huchida/work/venv_voice_mapping/lib64/python3.7/site-packages/django/core/handlers/exception.py(Line:77)	Invalid HTTP_HOST header: '18.216.231.209'. You may need to add '18.216.231.209' to ALLOWED_HOSTS.
2020-05-23 04:02:56,200	[ERROR]	/home/huchida/work/venv_voice_mapping/lib64/python3.7/site-packages/django/core/handlers/exception.py(Line:77)	Invalid HTTP_HOST header: '18.216.231.209'. You may need to add '18.216.231.209' to ALLOWED_HOSTS.
2020-05-23 04:02:56,646	[ERROR]	/home/huchida/work/venv_voice_mapping/lib64/python3.7/site-packages/django/core/handlers/exception.py(Line:77)	Invalid HTTP_HOST header: '18.216.231.209'. You may need to add '18.216.231.209' to ALLOWED_HOSTS.
2020-05-23 04:02:57,109	[ERROR]	/home/huchida/work/venv_voice_mapping/lib64/python3.7/site-packages/django/core/handlers/exception.py(Line:77)	Invalid HTTP_HOST header: '18.216.231.209'. You may need to add '18.216.231.209' to ALLOWED_HOSTS.
2020-05-23 04:02:57,570	[ERROR]	/home/huchida/work/venv_voice_mapping/lib64/python3.7/site-packages/django/core/handlers/exception.py(Line:77)	Invalid HTTP_HOST header: '18.216.231.209'. You may need to add '18.216.231.209' to ALLOWED_HOSTS.
2020-05-23 04:02:58,035	[ERROR]	/home/huchida/work/venv_voice_mapping/lib64/python3.7/site-packages/django/core/handlers/exception.py(Line:77)	Invalid HTTP_HOST header: '18.216.231.209'. You may need to add '18.216.231.209' to ALLOWED_HOSTS.
2020-05-23 04:02:58,501	[ERROR]	/home/huchida/work/venv_voice_mapping/lib64/python3.7/site-packages/django/core/handlers/exception.py(Line:77)	Invalid HTTP_HOST header: '18.216.231.209'. You may need to add '18.216.231.209' to ALLOWED_HOSTS.
2020-05-23 04:02:58,977	[ERROR]	/home/huchida/work/venv_voice_mapping/lib64/python3.7/site-packages/django/core/handlers/exception.py(Line:77)	Invalid HTTP_HOST header: '18.216.231.209'. You may need to add '18.216.231.209' to ALLOWED_HOSTS.
2020-05-23 04:02:59,415	[ERROR]	/home/huchida/work/venv_voice_mapping/lib64/python3.7/site-packages/django/core/handlers/exception.py(Line:77)	Invalid HTTP_HOST header: '18.216.231.209'. You may need to add '18.216.231.209' to ALLOWED_HOSTS.
2020-05-23 04:02:59,875	[ERROR]	/home/huchida/work/venv_voice_mapping/lib64/python3.7/site-packages/django/core/handlers/exception.py(Line:77)	Invalid HTTP_HOST header: '18.216.231.209:80'. You may need to add '18.216.231.209' to ALLOWED_HOSTS.
2020-05-23 04:24:49,708	[ERROR]	/home/huchida/work/venv_voice_mapping/lib64/python3.7/site-packages/django/core/handlers/exception.py(Line:77)	Invalid HTTP_HOST header: '127.0.0.1:8000'. You may need to add '127.0.0.1' to ALLOWED_HOSTS.
2020-05-23 06:23:28,832	[ERROR]	/home/huchida/work/venv_voice_mapping/lib64/python3.7/site-packages/django/core/handlers/exception.py(Line:77)	Invalid HTTP_HOST header: '18.216.231.209:80'. You may need to add '18.216.231.209' to ALLOWED_HOSTS.
2020-05-23 06:30:30,668	[ERROR]	/home/huchida/work/venv_voice_mapping/lib64/python3.7/site-packages/django/core/handlers/exception.py(Line:77)	Invalid HTTP_HOST header: '18.216.231.209:80'. You may need to add '18.216.231.209' to ALLOWED_HOSTS.
2020-05-23 06:30:30,808	[ERROR]	/home/huchida/work/venv_voice_mapping/lib64/python3.7/site-packages/django/core/handlers/exception.py(Line:77)	Invalid HTTP_HOST header: '18.216.231.209:80'. You may need to add '18.216.231.209' to ALLOWED_HOSTS.
2020-05-23 06:30:30,959	[ERROR]	/home/huchida/work/venv_voice_mapping/lib64/python3.7/site-packages/django/core/handlers/exception.py(Line:77)	Invalid HTTP_HOST header: '18.216.231.209:80'. You may need to add '18.216.231.209' to ALLOWED_HOSTS.
2020-05-23 06:41:53,350	[ERROR]	/home/huchida/work/venv_voice_mapping/lib64/python3.7/site-packages/django/core/handlers/exception.py(Line:77)	Invalid HTTP_HOST header: '18.216.231.209:80'. You may need to add '18.216.231.209' to ALLOWED_HOSTS.
2020-05-23 07:40:49,240	[ERROR]	/home/huchida/work/venv_voice_mapping/lib64/python3.7/site-packages/django/core/handlers/exception.py(Line:77)	Invalid HTTP_HOST header: '18.216.231.209'. You may need to add '18.216.231.209' to ALLOWED_HOSTS.
2020-05-23 07:40:49,787	[ERROR]	/home/huchida/work/venv_voice_mapping/lib64/python3.7/site-packages/django/core/handlers/exception.py(Line:77)	Invalid HTTP_HOST header: '18.216.231.209'. You may need to add '18.216.231.209' to ALLOWED_HOSTS.
2020-05-23 07:40:50,310	[ERROR]	/home/huchida/work/venv_voice_mapping/lib64/python3.7/site-packages/django/core/handlers/exception.py(Line:77)	Invalid HTTP_HOST header: '18.216.231.209'. You may need to add '18.216.231.209' to ALLOWED_HOSTS.
2020-05-23 07:40:50,833	[ERROR]	/home/huchida/work/venv_voice_mapping/lib64/python3.7/site-packages/django/core/handlers/exception.py(Line:77)	Invalid HTTP_HOST header: '18.216.231.209'. You may need to add '18.216.231.209' to ALLOWED_HOSTS.
2020-05-23 07:40:56,361	[ERROR]	/home/huchida/work/venv_voice_mapping/lib64/python3.7/site-packages/django/core/handlers/exception.py(Line:77)	Invalid HTTP_HOST header: '18.216.231.209:80'. You may need to add '18.216.231.209' to ALLOWED_HOSTS.
2020-05-23 08:47:00,724	[ERROR]	/home/huchida/work/venv_voice_mapping/lib64/python3.7/site-packages/django/core/handlers/exception.py(Line:77)	Invalid HTTP_HOST header: '18.216.231.209:80'. You may need to add '18.216.231.209' to ALLOWED_HOSTS.
2020-05-23 09:09:11,518	[ERROR]	/home/huchida/work/venv_voice_mapping/lib64/python3.7/site-packages/django/core/handlers/exception.py(Line:77)	Invalid HTTP_HOST header: '18.216.231.209:80'. You may need to add '18.216.231.209' to ALLOWED_HOSTS.
2020-05-23 09:48:22,608	[ERROR]	/home/huchida/work/venv_voice_mapping/lib64/python3.7/site-packages/django/core/handlers/exception.py(Line:77)	Invalid HTTP_HOST header: '18.216.231.209'. You may need to add '18.216.231.209' to ALLOWED_HOSTS.
2020-05-23 09:48:23,222	[ERROR]	/home/huchida/work/venv_voice_mapping/lib64/python3.7/site-packages/django/core/handlers/exception.py(Line:77)	Invalid HTTP_HOST header: '18.216.231.209'. You may need to add '18.216.231.209' to ALLOWED_HOSTS.
2020-05-23 09:49:56,824	[INFO]	/home/huchida/work/venv_voice_mapping/lib64/python3.7/site-packages/django/utils/autoreload.py(Line:598)	Watching for file changes with StatReloader
2020-05-23 09:51:20,013	[INFO]	/home/huchida/work/venv_voice_mapping/lib64/python3.7/site-packages/django/utils/autoreload.py(Line:598)	Watching for file changes with StatReloader
2020-05-23 10:24:17,415	[ERROR]	/home/huchida/work/venv_voice_mapping/lib64/python3.7/site-packages/django/core/handlers/exception.py(Line:77)	Invalid HTTP_HOST header: 'example.com'. You may need to add 'example.com' to ALLOWED_HOSTS.
2020-05-23 10:24:17,533	[ERROR]	/home/huchida/work/venv_voice_mapping/lib64/python3.7/site-packages/django/core/handlers/exception.py(Line:77)	Invalid HTTP_HOST header: '169.254.169.254'. You may need to add '169.254.169.254' to ALLOWED_HOSTS.
2020-05-23 10:24:17,649	[ERROR]	/home/huchida/work/venv_voice_mapping/lib64/python3.7/site-packages/django/core/handlers/exception.py(Line:77)	Invalid HTTP_HOST header: '[::ffff:a9fe:a9fe]'. You may need to add '[::ffff:a9fe:a9fe]' to ALLOWED_HOSTS.
2020-05-23 10:24:17,766	[ERROR]	/home/huchida/work/venv_voice_mapping/lib64/python3.7/site-packages/django/core/handlers/exception.py(Line:77)	Invalid HTTP_HOST header: '169.254.169.254'. You may need to add '169.254.169.254' to ALLOWED_HOSTS.
2020-05-23 10:24:17,884	[ERROR]	/home/huchida/work/venv_voice_mapping/lib64/python3.7/site-packages/django/core/handlers/exception.py(Line:77)	Invalid HTTP_HOST header: '[::ffff:a9fe:a9fe]'. You may need to add '[::ffff:a9fe:a9fe]' to ALLOWED_HOSTS.
2020-05-23 10:24:17,999	[ERROR]	/home/huchida/work/venv_voice_mapping/lib64/python3.7/site-packages/django/core/handlers/exception.py(Line:77)	Invalid HTTP_HOST header: 'example.com'. You may need to add 'example.com' to ALLOWED_HOSTS.
2020-05-23 10:24:18,115	[ERROR]	/home/huchida/work/venv_voice_mapping/lib64/python3.7/site-packages/django/core/handlers/exception.py(Line:77)	Invalid HTTP_HOST header: '169.254.169.254'. You may need to add '169.254.169.254' to ALLOWED_HOSTS.
2020-05-23 10:24:18,232	[ERROR]	/home/huchida/work/venv_voice_mapping/lib64/python3.7/site-packages/django/core/handlers/exception.py(Line:77)	Invalid HTTP_HOST header: '[::ffff:a9fe:a9fe]'. You may need to add '[::ffff:a9fe:a9fe]' to ALLOWED_HOSTS.
2020-05-23 10:24:18,349	[ERROR]	/home/huchida/work/venv_voice_mapping/lib64/python3.7/site-packages/django/core/handlers/exception.py(Line:77)	Invalid HTTP_HOST header: '169.254.169.254'. You may need to add '169.254.169.254' to ALLOWED_HOSTS.
2020-05-23 10:24:18,465	[ERROR]	/home/huchida/work/venv_voice_mapping/lib64/python3.7/site-packages/django/core/handlers/exception.py(Line:77)	Invalid HTTP_HOST header: '[::ffff:a9fe:a9fe]'. You may need to add '[::ffff:a9fe:a9fe]' to ALLOWED_HOSTS.
2020-05-23 10:26:37,801	[ERROR]	/home/huchida/work/venv_voice_mapping/lib64/python3.7/site-packages/django/core/handlers/exception.py(Line:77)	Invalid HTTP_HOST header: '18.216.231.209:80'. You may need to add '18.216.231.209' to ALLOWED_HOSTS.
2020-05-23 12:00:18,529	[ERROR]	/home/huchida/work/venv_voice_mapping/lib64/python3.7/site-packages/django/core/handlers/exception.py(Line:77)	Invalid HTTP_HOST header: '18.216.231.209'. You may need to add '18.216.231.209' to ALLOWED_HOSTS.
2020-05-23 12:37:29,720	[ERROR]	/home/huchida/work/venv_voice_mapping/lib64/python3.7/site-packages/django/core/handlers/exception.py(Line:77)	Invalid HTTP_HOST header: '18.216.231.209'. You may need to add '18.216.231.209' to ALLOWED_HOSTS.
2020-05-23 12:41:47,389	[ERROR]	/home/huchida/work/venv_voice_mapping/lib64/python3.7/site-packages/django/core/handlers/exception.py(Line:77)	Invalid HTTP_HOST header: '127.0.0.1'. You may need to add '127.0.0.1' to ALLOWED_HOSTS.
2020-05-23 13:17:44,609	[ERROR]	/home/huchida/work/venv_voice_mapping/lib64/python3.7/site-packages/django/core/handlers/exception.py(Line:77)	Invalid HTTP_HOST header: '18.216.231.209'. You may need to add '18.216.231.209' to ALLOWED_HOSTS.
2020-05-23 13:17:44,914	[ERROR]	/home/huchida/work/venv_voice_mapping/lib64/python3.7/site-packages/django/core/handlers/exception.py(Line:77)	Invalid HTTP_HOST header: '18.216.231.209'. You may need to add '18.216.231.209' to ALLOWED_HOSTS.
2020-05-23 14:45:47,073	[ERROR]	/home/huchida/work/venv_voice_mapping/lib64/python3.7/site-packages/django/core/handlers/exception.py(Line:77)	Invalid HTTP_HOST header: 'ec2-18-216-231-209.us-east-2.compute.amazonaws.com'. You may need to add 'ec2-18-216-231-209.us-east-2.compute.amazonaws.com' to ALLOWED_HOSTS.
2020-05-23 14:59:38,785	[ERROR]	/home/huchida/work/venv_voice_mapping/lib64/python3.7/site-packages/django/core/handlers/exception.py(Line:77)	Invalid HTTP_HOST header: '127.0.0.1:8000'. You may need to add '127.0.0.1' to ALLOWED_HOSTS.
2020-05-23 22:00:36,051	[ERROR]	/home/huchida/work/venv_voice_mapping/lib64/python3.7/site-packages/django/utils/log.py(Line:228)	Internal Server Error: /
Traceback (most recent call last):
  File "/home/huchida/work/venv_voice_mapping/lib64/python3.7/site-packages/django/core/handlers/exception.py", line 34, in inner
    response = get_response(request)
  File "/home/huchida/work/venv_voice_mapping/lib64/python3.7/site-packages/django/core/handlers/base.py", line 115, in _get_response
    response = self.process_exception_by_middleware(e, request)
  File "/home/huchida/work/venv_voice_mapping/lib64/python3.7/site-packages/django/core/handlers/base.py", line 113, in _get_response
    response = wrapped_callback(request, *callback_args, **callback_kwargs)
  File "/home/huchida/work/venv_voice_mapping/lib64/python3.7/site-packages/django/views/generic/base.py", line 71, in view
    return self.dispatch(request, *args, **kwargs)
  File "/home/huchida/work/venv_voice_mapping/lib64/python3.7/site-packages/django/views/generic/base.py", line 97, in dispatch
    return handler(request, *args, **kwargs)
  File "/home/huchida/work/venv_voice_mapping/lib64/python3.7/site-packages/django/views/generic/base.py", line 158, in get
    context = self.get_context_data(**kwargs)
  File "/home/huchida/work/venv_voice_mapping/VoiceMapping_Web/vmap/views.py", line 43, in get_context_data
    context["person1"] = self.person1
AttributeError: 'IndexView' object has no attribute 'person1'
2020-05-23 22:00:37,109	[WARNING]	/home/huchida/work/venv_voice_mapping/lib64/python3.7/site-packages/django/utils/log.py(Line:228)	Not Found: /favicon.ico
2020-05-23 22:06:08,252	[ERROR]	/home/huchida/work/venv_voice_mapping/lib64/python3.7/site-packages/django/utils/log.py(Line:228)	Internal Server Error: /
Traceback (most recent call last):
  File "/home/huchida/work/venv_voice_mapping/lib64/python3.7/site-packages/django/core/handlers/exception.py", line 34, in inner
    response = get_response(request)
  File "/home/huchida/work/venv_voice_mapping/lib64/python3.7/site-packages/django/core/handlers/base.py", line 115, in _get_response
    response = self.process_exception_by_middleware(e, request)
  File "/home/huchida/work/venv_voice_mapping/lib64/python3.7/site-packages/django/core/handlers/base.py", line 113, in _get_response
    response = wrapped_callback(request, *callback_args, **callback_kwargs)
  File "/home/huchida/work/venv_voice_mapping/lib64/python3.7/site-packages/django/views/generic/base.py", line 71, in view
    return self.dispatch(request, *args, **kwargs)
  File "/home/huchida/work/venv_voice_mapping/lib64/python3.7/site-packages/django/views/generic/base.py", line 97, in dispatch
    return handler(request, *args, **kwargs)
  File "/home/huchida/work/venv_voice_mapping/lib64/python3.7/site-packages/django/views/generic/base.py", line 158, in get
    context = self.get_context_data(**kwargs)
  File "/home/huchida/work/venv_voice_mapping/VoiceMapping_Web/vmap/views.py", line 43, in get_context_data
    context["person1"] = self.person1
AttributeError: 'IndexView' object has no attribute 'person1'
2020-05-23 22:12:54,686	[ERROR]	/home/huchida/work/venv_voice_mapping/lib64/python3.7/site-packages/django/utils/log.py(Line:228)	Internal Server Error: /
Traceback (most recent call last):
  File "/home/huchida/work/venv_voice_mapping/lib64/python3.7/site-packages/django/core/handlers/exception.py", line 34, in inner
    response = get_response(request)
  File "/home/huchida/work/venv_voice_mapping/lib64/python3.7/site-packages/django/core/handlers/base.py", line 115, in _get_response
    response = self.process_exception_by_middleware(e, request)
  File "/home/huchida/work/venv_voice_mapping/lib64/python3.7/site-packages/django/core/handlers/base.py", line 113, in _get_response
    response = wrapped_callback(request, *callback_args, **callback_kwargs)
  File "/home/huchida/work/venv_voice_mapping/lib64/python3.7/site-packages/django/views/generic/base.py", line 71, in view
    return self.dispatch(request, *args, **kwargs)
  File "/home/huchida/work/venv_voice_mapping/lib64/python3.7/site-packages/django/views/generic/base.py", line 97, in dispatch
    return handler(request, *args, **kwargs)
  File "/home/huchida/work/venv_voice_mapping/lib64/python3.7/site-packages/django/views/generic/base.py", line 158, in get
    context = self.get_context_data(**kwargs)
  File "/home/huchida/work/venv_voice_mapping/VoiceMapping_Web/vmap/views.py", line 43, in get_context_data
    context["person1"] = self.person1
AttributeError: 'IndexView' object has no attribute 'person1'
2020-05-24 10:02:52,559	[WARNING]	/home/huchida/work/venv_voice_mapping/lib64/python3.7/site-packages/django/utils/log.py(Line:228)	Not Found: /404.html
2020-05-24 10:06:36,073	[WARNING]	/home/huchida/work/venv_voice_mapping/lib64/python3.7/site-packages/django/utils/log.py(Line:228)	Not Found: /favicon.ico
2020-05-24 10:06:37,412	[WARNING]	/home/huchida/work/venv_voice_mapping/lib64/python3.7/site-packages/django/utils/log.py(Line:228)	Not Found: /404.html
2020-05-24 10:07:58,794	[WARNING]	/home/huchida/work/venv_voice_mapping/lib64/python3.7/site-packages/django/utils/log.py(Line:228)	Not Found: /404.html
2020-05-24 10:13:57,446	[WARNING]	/home/huchida/work/venv_voice_mapping/lib64/python3.7/site-packages/django/utils/log.py(Line:228)	Not Found: /404.html
2020-05-24 10:14:07,961	[ERROR]	/home/huchida/work/venv_voice_mapping/lib64/python3.7/site-packages/django/utils/log.py(Line:228)	Internal Server Error: /voice_mapping/
Traceback (most recent call last):
  File "/home/huchida/work/venv_voice_mapping/lib64/python3.7/site-packages/django/core/handlers/exception.py", line 34, in inner
    response = get_response(request)
  File "/home/huchida/work/venv_voice_mapping/lib64/python3.7/site-packages/django/core/handlers/base.py", line 115, in _get_response
    response = self.process_exception_by_middleware(e, request)
  File "/home/huchida/work/venv_voice_mapping/lib64/python3.7/site-packages/django/core/handlers/base.py", line 113, in _get_response
    response = wrapped_callback(request, *callback_args, **callback_kwargs)
  File "/home/huchida/work/venv_voice_mapping/lib64/python3.7/site-packages/django/views/generic/base.py", line 71, in view
    return self.dispatch(request, *args, **kwargs)
  File "/home/huchida/work/venv_voice_mapping/lib64/python3.7/site-packages/django/views/generic/base.py", line 97, in dispatch
    return handler(request, *args, **kwargs)
  File "/home/huchida/work/venv_voice_mapping/lib64/python3.7/site-packages/django/views/generic/edit.py", line 142, in post
    return self.form_valid(form)
  File "/home/huchida/work/venv_voice_mapping/lib64/python3.7/site-packages/django/views/generic/edit.py", line 57, in form_valid
    return HttpResponseRedirect(self.get_success_url())
  File "/home/huchida/work/venv_voice_mapping/lib64/python3.7/site-packages/django/views/generic/edit.py", line 52, in get_success_url
    raise ImproperlyConfigured("No URL to redirect to. Provide a success_url.")
django.core.exceptions.ImproperlyConfigured: No URL to redirect to. Provide a success_url.
2020-05-24 10:15:02,225	[WARNING]	/home/huchida/work/venv_voice_mapping/lib64/python3.7/site-packages/django/utils/log.py(Line:228)	Not Found: /404.html
2020-05-24 10:15:07,942	[ERROR]	/home/huchida/work/venv_voice_mapping/lib64/python3.7/site-packages/django/utils/log.py(Line:228)	Internal Server Error: /voice_mapping/
Traceback (most recent call last):
  File "/home/huchida/work/venv_voice_mapping/lib64/python3.7/site-packages/django/core/handlers/exception.py", line 34, in inner
    response = get_response(request)
  File "/home/huchida/work/venv_voice_mapping/lib64/python3.7/site-packages/django/core/handlers/base.py", line 115, in _get_response
    response = self.process_exception_by_middleware(e, request)
  File "/home/huchida/work/venv_voice_mapping/lib64/python3.7/site-packages/django/core/handlers/base.py", line 113, in _get_response
    response = wrapped_callback(request, *callback_args, **callback_kwargs)
  File "/home/huchida/work/venv_voice_mapping/lib64/python3.7/site-packages/django/views/generic/base.py", line 71, in view
    return self.dispatch(request, *args, **kwargs)
  File "/home/huchida/work/venv_voice_mapping/lib64/python3.7/site-packages/django/views/generic/base.py", line 97, in dispatch
    return handler(request, *args, **kwargs)
  File "/home/huchida/work/venv_voice_mapping/lib64/python3.7/site-packages/django/views/generic/edit.py", line 142, in post
    return self.form_valid(form)
  File "/home/huchida/work/venv_voice_mapping/lib64/python3.7/site-packages/django/views/generic/edit.py", line 57, in form_valid
    return HttpResponseRedirect(self.get_success_url())
  File "/home/huchida/work/venv_voice_mapping/lib64/python3.7/site-packages/django/views/generic/edit.py", line 52, in get_success_url
    raise ImproperlyConfigured("No URL to redirect to. Provide a success_url.")
django.core.exceptions.ImproperlyConfigured: No URL to redirect to. Provide a success_url.
2020-05-24 10:17:29,698	[WARNING]	/home/huchida/work/venv_voice_mapping/lib64/python3.7/site-packages/django/utils/log.py(Line:228)	Not Found: /404.html
2020-05-24 10:17:36,789	[WARNING]	/home/huchida/work/venv_voice_mapping/lib64/python3.7/site-packages/django/utils/log.py(Line:228)	Not Found: /404.html
2020-05-24 10:36:51,696	[WARNING]	/home/huchida/work/venv_voice_mapping/lib64/python3.7/site-packages/django/utils/log.py(Line:228)	Not Found: /usr/share/nginx/html/media/moka.jpg
2020-05-24 10:36:56,218	[WARNING]	/home/huchida/work/venv_voice_mapping/lib64/python3.7/site-packages/django/utils/log.py(Line:228)	Not Found: /usr/share/nginx/html/media/moka.jpg
2020-05-24 10:42:59,056	[WARNING]	/home/huchida/work/venv_voice_mapping/lib64/python3.7/site-packages/django/utils/log.py(Line:228)	Not Found: /favicon.ico
2020-05-24 10:43:18,207	[WARNING]	/home/huchida/work/venv_voice_mapping/lib64/python3.7/site-packages/django/utils/log.py(Line:228)	Not Found: /favicon.ico
2020-05-24 10:44:22,003	[ERROR]	/home/huchida/work/venv_voice_mapping/lib64/python3.7/site-packages/django/core/handlers/exception.py(Line:77)	Invalid HTTP_HOST header: 'example.com'. You may need to add 'example.com' to ALLOWED_HOSTS.
2020-05-24 10:44:22,004	[WARNING]	/home/huchida/work/venv_voice_mapping/lib64/python3.7/site-packages/django/utils/log.py(Line:228)	Bad Request: /
2020-05-24 10:44:22,107	[ERROR]	/home/huchida/work/venv_voice_mapping/lib64/python3.7/site-packages/django/core/handlers/exception.py(Line:77)	Invalid HTTP_HOST header: '169.254.169.254'. You may need to add '169.254.169.254' to ALLOWED_HOSTS.
2020-05-24 10:44:22,107	[WARNING]	/home/huchida/work/venv_voice_mapping/lib64/python3.7/site-packages/django/utils/log.py(Line:228)	Bad Request: /
2020-05-24 10:44:22,211	[ERROR]	/home/huchida/work/venv_voice_mapping/lib64/python3.7/site-packages/django/core/handlers/exception.py(Line:77)	Invalid HTTP_HOST header: '[::ffff:a9fe:a9fe]'. You may need to add '[::ffff:a9fe:a9fe]' to ALLOWED_HOSTS.
2020-05-24 10:44:22,212	[WARNING]	/home/huchida/work/venv_voice_mapping/lib64/python3.7/site-packages/django/utils/log.py(Line:228)	Bad Request: /
2020-05-24 10:44:22,315	[ERROR]	/home/huchida/work/venv_voice_mapping/lib64/python3.7/site-packages/django/core/handlers/exception.py(Line:77)	Invalid HTTP_HOST header: '169.254.169.254'. You may need to add '169.254.169.254' to ALLOWED_HOSTS.
2020-05-24 10:44:22,315	[WARNING]	/home/huchida/work/venv_voice_mapping/lib64/python3.7/site-packages/django/utils/log.py(Line:228)	Bad Request: /latest/dynamic/instance-identity/document
2020-05-24 10:44:22,419	[ERROR]	/home/huchida/work/venv_voice_mapping/lib64/python3.7/site-packages/django/core/handlers/exception.py(Line:77)	Invalid HTTP_HOST header: '[::ffff:a9fe:a9fe]'. You may need to add '[::ffff:a9fe:a9fe]' to ALLOWED_HOSTS.
2020-05-24 10:44:22,419	[WARNING]	/home/huchida/work/venv_voice_mapping/lib64/python3.7/site-packages/django/utils/log.py(Line:228)	Bad Request: /latest/dynamic/instance-identity/document
2020-05-24 10:44:22,523	[ERROR]	/home/huchida/work/venv_voice_mapping/lib64/python3.7/site-packages/django/core/handlers/exception.py(Line:77)	Invalid HTTP_HOST header: 'example.com'. You may need to add 'example.com' to ALLOWED_HOSTS.
2020-05-24 10:44:22,523	[WARNING]	/home/huchida/work/venv_voice_mapping/lib64/python3.7/site-packages/django/utils/log.py(Line:228)	Bad Request: /
2020-05-24 10:44:22,627	[ERROR]	/home/huchida/work/venv_voice_mapping/lib64/python3.7/site-packages/django/core/handlers/exception.py(Line:77)	Invalid HTTP_HOST header: '169.254.169.254'. You may need to add '169.254.169.254' to ALLOWED_HOSTS.
2020-05-24 10:44:22,627	[WARNING]	/home/huchida/work/venv_voice_mapping/lib64/python3.7/site-packages/django/utils/log.py(Line:228)	Bad Request: /
2020-05-24 10:44:22,730	[ERROR]	/home/huchida/work/venv_voice_mapping/lib64/python3.7/site-packages/django/core/handlers/exception.py(Line:77)	Invalid HTTP_HOST header: '[::ffff:a9fe:a9fe]'. You may need to add '[::ffff:a9fe:a9fe]' to ALLOWED_HOSTS.
2020-05-24 10:44:22,730	[WARNING]	/home/huchida/work/venv_voice_mapping/lib64/python3.7/site-packages/django/utils/log.py(Line:228)	Bad Request: /
2020-05-24 10:44:22,833	[ERROR]	/home/huchida/work/venv_voice_mapping/lib64/python3.7/site-packages/django/core/handlers/exception.py(Line:77)	Invalid HTTP_HOST header: '169.254.169.254'. You may need to add '169.254.169.254' to ALLOWED_HOSTS.
2020-05-24 10:44:22,834	[WARNING]	/home/huchida/work/venv_voice_mapping/lib64/python3.7/site-packages/django/utils/log.py(Line:228)	Bad Request: /latest/dynamic/instance-identity/document
2020-05-24 10:44:22,937	[ERROR]	/home/huchida/work/venv_voice_mapping/lib64/python3.7/site-packages/django/core/handlers/exception.py(Line:77)	Invalid HTTP_HOST header: '[::ffff:a9fe:a9fe]'. You may need to add '[::ffff:a9fe:a9fe]' to ALLOWED_HOSTS.
2020-05-24 10:44:22,937	[WARNING]	/home/huchida/work/venv_voice_mapping/lib64/python3.7/site-packages/django/utils/log.py(Line:228)	Bad Request: /latest/dynamic/instance-identity/document
2020-05-24 10:49:13,204	[WARNING]	/home/huchida/work/venv_voice_mapping/lib64/python3.7/site-packages/django/utils/log.py(Line:228)	Not Found: /favicon.ico
2020-05-24 10:49:27,844	[WARNING]	/home/huchida/work/venv_voice_mapping/lib64/python3.7/site-packages/django/utils/log.py(Line:228)	Not Found: /favicon.ico
2020-05-24 11:05:36,299	[WARNING]	/home/huchida/work/venv_voice_mapping/lib64/python3.7/site-packages/django/utils/log.py(Line:228)	Not Found: /favicon.ico
2020-05-24 21:59:52,707	[ERROR]	/home/huchida/work/venv_voice_mapping/lib64/python3.7/site-packages/django/core/handlers/exception.py(Line:77)	Invalid HTTP_HOST header: '18.216.231.209'. You may need to add '18.216.231.209' to ALLOWED_HOSTS.
2020-05-24 21:59:53,020	[WARNING]	/home/huchida/work/venv_voice_mapping/lib64/python3.7/site-packages/django/utils/log.py(Line:228)	Bad Request: /
2020-05-24 23:31:05,881	[WARNING]	/home/huchida/work/venv_voice_mapping/lib64/python3.7/site-packages/django/utils/log.py(Line:228)	Not Found: /favicon.ico
2020-05-25 08:47:22,698	[WARNING]	/home/huchida/work/venv_voice_mapping/lib64/python3.7/site-packages/django/utils/log.py(Line:228)	Not Found: /favicon.ico
2020-05-25 13:14:00,227	[WARNING]	/home/huchida/work/venv_voice_mapping/lib64/python3.7/site-packages/django/utils/log.py(Line:228)	Not Found: /favicon.ico
2020-05-25 20:28:05,569	[WARNING]	/home/huchida/work/venv_voice_mapping/lib64/python3.7/site-packages/django/utils/log.py(Line:228)	Not Found: /favicon.ico
2020-05-25 20:28:08,635	[WARNING]	/home/huchida/work/venv_voice_mapping/lib64/python3.7/site-packages/django/utils/log.py(Line:228)	Not Found: /favicon.ico
2020-05-25 20:28:12,969	[WARNING]	/home/huchida/work/venv_voice_mapping/lib64/python3.7/site-packages/django/utils/log.py(Line:228)	Not Found: /favicon.ico
2020-05-25 20:28:24,620	[WARNING]	/home/huchida/work/venv_voice_mapping/lib64/python3.7/site-packages/django/utils/log.py(Line:228)	Not Found: /favicon.ico
2020-05-25 22:39:50,745	[ERROR]	/home/huchida/work/venv_voice_mapping/lib64/python3.7/site-packages/django/core/handlers/exception.py(Line:77)	Invalid HTTP_HOST header: 'example.com'. You may need to add 'example.com' to ALLOWED_HOSTS.
2020-05-25 22:39:50,745	[WARNING]	/home/huchida/work/venv_voice_mapping/lib64/python3.7/site-packages/django/utils/log.py(Line:228)	Bad Request: /
2020-05-25 22:39:50,957	[ERROR]	/home/huchida/work/venv_voice_mapping/lib64/python3.7/site-packages/django/core/handlers/exception.py(Line:77)	Invalid HTTP_HOST header: '169.254.169.254'. You may need to add '169.254.169.254' to ALLOWED_HOSTS.
2020-05-25 22:39:50,957	[WARNING]	/home/huchida/work/venv_voice_mapping/lib64/python3.7/site-packages/django/utils/log.py(Line:228)	Bad Request: /
2020-05-25 22:39:51,173	[ERROR]	/home/huchida/work/venv_voice_mapping/lib64/python3.7/site-packages/django/core/handlers/exception.py(Line:77)	Invalid HTTP_HOST header: '[::ffff:a9fe:a9fe]'. You may need to add '[::ffff:a9fe:a9fe]' to ALLOWED_HOSTS.
2020-05-25 22:39:51,173	[WARNING]	/home/huchida/work/venv_voice_mapping/lib64/python3.7/site-packages/django/utils/log.py(Line:228)	Bad Request: /
2020-05-25 22:39:51,386	[ERROR]	/home/huchida/work/venv_voice_mapping/lib64/python3.7/site-packages/django/core/handlers/exception.py(Line:77)	Invalid HTTP_HOST header: '169.254.169.254'. You may need to add '169.254.169.254' to ALLOWED_HOSTS.
2020-05-25 22:39:51,386	[WARNING]	/home/huchida/work/venv_voice_mapping/lib64/python3.7/site-packages/django/utils/log.py(Line:228)	Bad Request: /latest/dynamic/instance-identity/document
2020-05-25 22:39:51,599	[ERROR]	/home/huchida/work/venv_voice_mapping/lib64/python3.7/site-packages/django/core/handlers/exception.py(Line:77)	Invalid HTTP_HOST header: '[::ffff:a9fe:a9fe]'. You may need to add '[::ffff:a9fe:a9fe]' to ALLOWED_HOSTS.
2020-05-25 22:39:51,599	[WARNING]	/home/huchida/work/venv_voice_mapping/lib64/python3.7/site-packages/django/utils/log.py(Line:228)	Bad Request: /latest/dynamic/instance-identity/document
2020-05-25 22:48:29,815	[ERROR]	/home/huchida/work/venv_voice_mapping/lib64/python3.7/site-packages/django/core/handlers/exception.py(Line:77)	Invalid HTTP_HOST header: '18.216.231.209'. You may need to add '18.216.231.209' to ALLOWED_HOSTS.
2020-05-25 22:48:29,815	[WARNING]	/home/huchida/work/venv_voice_mapping/lib64/python3.7/site-packages/django/utils/log.py(Line:228)	Bad Request: /api/jsonws/invoke
2020-05-26 03:37:10,377	[ERROR]	/home/huchida/work/venv_voice_mapping/lib64/python3.7/site-packages/django/core/handlers/exception.py(Line:77)	Invalid HTTP_HOST header: '18.216.231.209'. You may need to add '18.216.231.209' to ALLOWED_HOSTS.
2020-05-26 03:37:10,377	[WARNING]	/home/huchida/work/venv_voice_mapping/lib64/python3.7/site-packages/django/utils/log.py(Line:228)	Bad Request: /solr/admin/info/system
2020-05-26 03:45:45,026	[ERROR]	/home/huchida/work/venv_voice_mapping/lib64/python3.7/site-packages/django/core/handlers/exception.py(Line:77)	Invalid HTTP_HOST header: '18.216.231.209'. You may need to add '18.216.231.209' to ALLOWED_HOSTS.
2020-05-26 03:45:45,026	[WARNING]	/home/huchida/work/venv_voice_mapping/lib64/python3.7/site-packages/django/utils/log.py(Line:228)	Bad Request: /
2020-05-26 03:45:45,625	[ERROR]	/home/huchida/work/venv_voice_mapping/lib64/python3.7/site-packages/django/core/handlers/exception.py(Line:77)	Invalid HTTP_HOST header: '18.216.231.209'. You may need to add '18.216.231.209' to ALLOWED_HOSTS.
2020-05-26 03:45:45,625	[WARNING]	/home/huchida/work/venv_voice_mapping/lib64/python3.7/site-packages/django/utils/log.py(Line:228)	Bad Request: /
2020-05-26 03:59:40,742	[ERROR]	/home/huchida/work/venv_voice_mapping/lib64/python3.7/site-packages/django/core/handlers/exception.py(Line:77)	Invalid HTTP_HOST header: '18.216.231.209'. You may need to add '18.216.231.209' to ALLOWED_HOSTS.
2020-05-26 03:59:40,742	[WARNING]	/home/huchida/work/venv_voice_mapping/lib64/python3.7/site-packages/django/utils/log.py(Line:228)	Bad Request: /index.php
2020-05-26 04:43:19,753	[ERROR]	/home/huchida/work/venv_voice_mapping/lib64/python3.7/site-packages/django/core/handlers/exception.py(Line:77)	Invalid HTTP_HOST header: '18.216.231.209'. You may need to add '18.216.231.209' to ALLOWED_HOSTS.
2020-05-26 04:43:19,753	[WARNING]	/home/huchida/work/venv_voice_mapping/lib64/python3.7/site-packages/django/utils/log.py(Line:228)	Bad Request: /
2020-05-26 06:50:03,828	[ERROR]	/home/huchida/work/venv_voice_mapping/lib64/python3.7/site-packages/django/core/handlers/exception.py(Line:77)	Invalid HTTP_HOST header: '18.216.231.209'. You may need to add '18.216.231.209' to ALLOWED_HOSTS.
2020-05-26 06:50:03,829	[WARNING]	/home/huchida/work/venv_voice_mapping/lib64/python3.7/site-packages/django/utils/log.py(Line:228)	Bad Request: /api/jsonws/invoke
2020-05-26 07:09:11,564	[ERROR]	/home/huchida/work/venv_voice_mapping/lib64/python3.7/site-packages/django/core/handlers/exception.py(Line:77)	Invalid HTTP_HOST header: '18.216.231.209:443'. You may need to add '18.216.231.209' to ALLOWED_HOSTS.
2020-05-26 07:09:11,564	[WARNING]	/home/huchida/work/venv_voice_mapping/lib64/python3.7/site-packages/django/utils/log.py(Line:228)	Bad Request: /index.php
2020-05-26 07:09:51,854	[ERROR]	/home/huchida/work/venv_voice_mapping/lib64/python3.7/site-packages/django/core/handlers/exception.py(Line:77)	Invalid HTTP_HOST header: '18.216.231.209:443'. You may need to add '18.216.231.209' to ALLOWED_HOSTS.
2020-05-26 07:09:51,855	[WARNING]	/home/huchida/work/venv_voice_mapping/lib64/python3.7/site-packages/django/utils/log.py(Line:228)	Bad Request: /
2020-05-26 07:28:13,856	[ERROR]	/home/huchida/work/venv_voice_mapping/lib64/python3.7/site-packages/django/core/handlers/exception.py(Line:77)	Invalid HTTP_HOST header: '18.216.231.209:443'. You may need to add '18.216.231.209' to ALLOWED_HOSTS.
2020-05-26 07:28:13,856	[WARNING]	/home/huchida/work/venv_voice_mapping/lib64/python3.7/site-packages/django/utils/log.py(Line:228)	Bad Request: /api/jsonws/invoke
2020-05-26 07:58:00,161	[ERROR]	/home/huchida/work/venv_voice_mapping/lib64/python3.7/site-packages/django/core/handlers/exception.py(Line:77)	Invalid HTTP_HOST header: '18.216.231.209:443'. You may need to add '18.216.231.209' to ALLOWED_HOSTS.
2020-05-26 07:58:00,161	[WARNING]	/home/huchida/work/venv_voice_mapping/lib64/python3.7/site-packages/django/utils/log.py(Line:228)	Bad Request: /
2020-05-26 08:43:40,659	[ERROR]	/home/huchida/work/venv_voice_mapping/lib64/python3.7/site-packages/django/core/handlers/exception.py(Line:77)	Invalid HTTP_HOST header: '18.216.231.209'. You may need to add '18.216.231.209' to ALLOWED_HOSTS.
2020-05-26 08:43:40,660	[WARNING]	/home/huchida/work/venv_voice_mapping/lib64/python3.7/site-packages/django/utils/log.py(Line:228)	Bad Request: /
2020-05-26 08:46:22,850	[ERROR]	/home/huchida/work/venv_voice_mapping/lib64/python3.7/site-packages/django/core/handlers/exception.py(Line:77)	Invalid HTTP_HOST header: '18.216.231.209:443'. You may need to add '18.216.231.209' to ALLOWED_HOSTS.
2020-05-26 08:46:22,850	[WARNING]	/home/huchida/work/venv_voice_mapping/lib64/python3.7/site-packages/django/utils/log.py(Line:228)	Bad Request: /
2020-05-26 09:21:29,272	[ERROR]	/home/huchida/work/venv_voice_mapping/lib64/python3.7/site-packages/django/core/handlers/exception.py(Line:77)	Invalid HTTP_HOST header: '18.216.231.209:443'. You may need to add '18.216.231.209' to ALLOWED_HOSTS.
2020-05-26 09:21:29,272	[WARNING]	/home/huchida/work/venv_voice_mapping/lib64/python3.7/site-packages/django/utils/log.py(Line:228)	Bad Request: /vendor/phpunit/phpunit/src/Util/PHP/eval-stdin.php
2020-05-26 09:21:29,597	[ERROR]	/home/huchida/work/venv_voice_mapping/lib64/python3.7/site-packages/django/core/handlers/exception.py(Line:77)	Invalid HTTP_HOST header: '18.216.231.209:443'. You may need to add '18.216.231.209' to ALLOWED_HOSTS.
2020-05-26 09:21:29,597	[WARNING]	/home/huchida/work/venv_voice_mapping/lib64/python3.7/site-packages/django/utils/log.py(Line:228)	Bad Request: /vendor/phpunit/phpunit/src/Util/PHP/eval-stdin.php
2020-05-26 10:52:29,535	[ERROR]	/home/huchida/work/venv_voice_mapping/lib64/python3.7/site-packages/django/core/handlers/exception.py(Line:77)	Invalid HTTP_HOST header: 'example.com'. You may need to add 'example.com' to ALLOWED_HOSTS.
2020-05-26 10:52:29,535	[WARNING]	/home/huchida/work/venv_voice_mapping/lib64/python3.7/site-packages/django/utils/log.py(Line:228)	Bad Request: /
2020-05-26 10:52:29,748	[ERROR]	/home/huchida/work/venv_voice_mapping/lib64/python3.7/site-packages/django/core/handlers/exception.py(Line:77)	Invalid HTTP_HOST header: '169.254.169.254'. You may need to add '169.254.169.254' to ALLOWED_HOSTS.
2020-05-26 10:52:29,748	[WARNING]	/home/huchida/work/venv_voice_mapping/lib64/python3.7/site-packages/django/utils/log.py(Line:228)	Bad Request: /
2020-05-26 10:52:29,962	[ERROR]	/home/huchida/work/venv_voice_mapping/lib64/python3.7/site-packages/django/core/handlers/exception.py(Line:77)	Invalid HTTP_HOST header: '[::ffff:a9fe:a9fe]'. You may need to add '[::ffff:a9fe:a9fe]' to ALLOWED_HOSTS.
2020-05-26 10:52:29,962	[WARNING]	/home/huchida/work/venv_voice_mapping/lib64/python3.7/site-packages/django/utils/log.py(Line:228)	Bad Request: /
2020-05-26 10:52:30,176	[ERROR]	/home/huchida/work/venv_voice_mapping/lib64/python3.7/site-packages/django/core/handlers/exception.py(Line:77)	Invalid HTTP_HOST header: '169.254.169.254'. You may need to add '169.254.169.254' to ALLOWED_HOSTS.
2020-05-26 10:52:30,177	[WARNING]	/home/huchida/work/venv_voice_mapping/lib64/python3.7/site-packages/django/utils/log.py(Line:228)	Bad Request: /latest/dynamic/instance-identity/document
2020-05-26 10:52:30,389	[ERROR]	/home/huchida/work/venv_voice_mapping/lib64/python3.7/site-packages/django/core/handlers/exception.py(Line:77)	Invalid HTTP_HOST header: '[::ffff:a9fe:a9fe]'. You may need to add '[::ffff:a9fe:a9fe]' to ALLOWED_HOSTS.
2020-05-26 10:52:30,389	[WARNING]	/home/huchida/work/venv_voice_mapping/lib64/python3.7/site-packages/django/utils/log.py(Line:228)	Bad Request: /latest/dynamic/instance-identity/document
2020-05-26 11:43:21,821	[ERROR]	/home/huchida/work/venv_voice_mapping/lib64/python3.7/site-packages/django/core/handlers/exception.py(Line:77)	Invalid HTTP_HOST header: '18.216.231.209'. You may need to add '18.216.231.209' to ALLOWED_HOSTS.
2020-05-26 11:43:21,822	[WARNING]	/home/huchida/work/venv_voice_mapping/lib64/python3.7/site-packages/django/utils/log.py(Line:228)	Bad Request: /
2020-05-26 12:13:16,800	[ERROR]	/home/huchida/work/venv_voice_mapping/lib64/python3.7/site-packages/django/core/handlers/exception.py(Line:77)	Invalid HTTP_HOST header: '18.216.231.209'. You may need to add '18.216.231.209' to ALLOWED_HOSTS.
2020-05-26 12:13:16,800	[WARNING]	/home/huchida/work/venv_voice_mapping/lib64/python3.7/site-packages/django/utils/log.py(Line:228)	Bad Request: /
2020-05-26 12:55:50,018	[ERROR]	/home/huchida/work/venv_voice_mapping/lib64/python3.7/site-packages/django/core/handlers/exception.py(Line:77)	Invalid HTTP_HOST header: '18.216.231.209'. You may need to add '18.216.231.209' to ALLOWED_HOSTS.
2020-05-26 12:55:50,019	[WARNING]	/home/huchida/work/venv_voice_mapping/lib64/python3.7/site-packages/django/utils/log.py(Line:228)	Bad Request: /
